Workbook

Sheet Inputs
A1: Secure ECU Package: pricing model inputs
A2: Edit only blue cells. Yellow = key assumptions to replace with your own data. All other sheets recalculate.
A4: Parameter | B4: Value | C4: Unit | D4: Source / note
A5: Estimate point used (1 = Low, 2 = Mid, 3 = High) | B5: 2 | C5: 1/2/3 | D5: Picks which module-hours column drives all prices (Mid = average of Low and High).
A6: Hours per person-month | B6: 160 | C6: h | D6: Same basis as Phase 3 pricing-landscape.md.
A7: Internal loaded cost per hour | B7: 45 | C7: EUR/h | D7: Assumption: EUR 6-8k per senior person-month in Cairo incl. tools, LLM usage, overhead. Founders to replace.
A8: Evidence overhead (% of core engineering hours) | B8: 0.3 | C8: % | D8: Assumption: ASPICE SWE.2-6 work products + traceability for the scope. Founders to replace.
A9: PM, reviews and named sign-off (% of core + evidence) | B9: 0.1 | C9: % | D9: Assumption.
A10: AI saving on engineering hours | B10: 0.15 | C10: % | D10: Assumption, unmeasured. Capgemini (Oct 2026): high-value adopters report 17% faster cycles, 19% higher productivity. Set 0% for a no-AI baseline.
A11: AI saving on evidence hours | B11: 0.15 | C11: % | D11: Assumption, unmeasured.
A12: Contingency on our hours (fixed-price risk) | B12: 0.15 | C12: % | D12: Assumption: covers estimation error on a fixed price.
A13: Guarantee reserve (% of price) | B13: 0.1 | C13: % | D13: Assumption: funds free fixes of findings on our scope (offer guarantee).
A14: Target gross margin (% of price) | B14: 0.35 | C14: % | D14: Assumption: founders' choice.
A15: Reference market rate for value-based price | B15: 95 | C15: EUR/h | D15: DACH IT freelancer median EUR 95/h (freelancermap 2026), the buyer's most common alternative (Phase 4 A1).
A16: AI pass-through to customer (% of AI saving) | B16: 0.5 | C16: % | D16: Founders' choice: share of the AI saving given back in the value-based price (Phase 4: 'AI savings on your invoice').
... A20: Working weeks per year | B20: 44 | C20: weeks | D20: Assumption.
A22: Market reference rates (customer's alternative)
A23: Alternative | B23: Low (EUR/h) | C23: High (EUR/h) | D23: Source / note
A24: German ESP / vendor services (onsite) | B24: 85 | C24: 130 | D24: Phase 3 pricing-landscape.md (EUR 85-130/h).
A25: DACH freelancer | B25: 80 | C25: 120 | D25: freelancermap 2026: median EUR 95/h, range 80-120 (Phase 4 A1).
A26: Eastern Europe ESP | B26: 45 | C26: 75 | D26: Phase 3 pricing-landscape.md.
A27: India / Egypt ESP (T&M) | B27: 23 | C27: 41 | D27: Phase 3: USD 25-45/h, i.e. EUR 3.6-6.5k per PM / 160 h.

Sheet Modules
A1: Effort per module: baseline hours for ONE new ECU, without AI
A2: Edit blue cells. Low/High hours are Claude's split of your 3-6 person-month total (480-960 h) across modules; replace them with your own numbers from past programmes. Spare rows M9-M10 can hold extra modules.
A4: ID | B4: Module / work item | C4: What's included | D4: Low (h) | E4: High (h) | F4: Hours used (h) | G4: Founder notes
A5: M1 | B5: Scope lock and setup | C5: Security requirements / TARA goals review; stack, MCU, HSM and bootloader audit; acceptance tests; project setup | D5: 32 | E5: 56 | F5: =CHOOSE(Inputs!$B$5,D5,(D5+E5)/2,E5)
A6: M2 | B6: HSM integration and HSM updater | C6: HSM firmware integration, host-HSM communication, HSM updater from bootloader/OTA | D6: 96 | E6: 192 | F6: =CHOOSE(Inputs!$B$5,D6,(D6+E6)/2,E6)
A7: M3 | B7: Crypto stack | C7: Csm / CryIf / crypto driver configuration and integration | D7: 56 | E7: 112 | F7: =CHOOSE(Inputs!$B$5,D7,(D7+E7)/2,E7)
A8: M4 | B8: Key handling (KeyM) | C8: KeyM, key set, key storage (NvM) for the agreed keys | D8: 32 | E8: 64 | F8: =CHOOSE(Inputs!$B$5,D8,(D8+E8)/2,E8)
A9: M5 | B9: Secure boot | C9: Boot chain bootloader -> HSM, incl. OTA path where in scope | D9: 96 | E9: 192 | F9: =CHOOSE(Inputs!$B$5,D9,(D9+E9)/2,E9)
A10: M6 | B10: Secure flashing and secure diagnostics | C10: Secure flashing, SecurityAccess / authentication services | D10: 56 | E10: 112 | F10: =CHOOSE(Inputs!$B$5,D10,(D10+E10)/2,E10)
A11: M7 | B11: Secure communication (SecOC / FVM) | C11: SecOC and freshness value management, MAC verification on the bus | D11: 72 | E11: 144 | F11: =CHOOSE(Inputs!$B$5,D11,(D11+E11)/2,E11)
A12: M8 | B12: On-target acceptance testing | C12: Acceptance test execution, debugging, test report | D12: 40 | E12: 88 | F12: =CHOOSE(Inputs!$B$5,D12,(D12+E12)/2,E12)
A13: M9 | B13: (spare: add a module) | D13: 0 | E13: 0 | F13: =CHOOSE(Inputs!$B$5,D13,(D13+E13)/2,E13)
A14: M10 | B14: (spare: add a module) | D14: 0 | E14: 0 | F14: =CHOOSE(Inputs!$B$5,D14,(D14+E14)/2,E14)
B15: Total | D15: =SUM(D5:D14) | E15: =SUM(E5:E14) | F15: =SUM(F5:F14)
B16: Total in person-months | D16: =D15/Inputs!$B$6 | E16: =E15/Inputs!$B$6 | F16: =F15/Inputs!$B$6

Sheet Packages
A1: Packages: which modules each package contains, and its price
A2: Factor per module: 1 = full new work, 0.3-0.6 = partial / reused work (derivatives), 0 = not included. Edit blue factors; everything below is calculated.
A4: ID | B4: Module | C4: P1 Secure ECU Package (new ECU) | D4: P2 Secure ECU Derivative | E4: P3 Secure Boot & Flashing | F4: P4 Secure Communication (SecOC)
A5: =Modules!A5 | B5: =Modules!B5 | C5: 1 | D5: 0.5 | E5: 1 | F5: 0.7
A6: =Modules!A6 | B6: =Modules!B6 | C6: 1 | D6: 0.3 | E6: 1 | F6: 0
A7: =Modules!A7 | B7: =Modules!B7 | C7: 1 | D7: 0.3 | E7: 1 | F7: 0.5
A8: =Modules!A8 | B8: =Modules!B8 | C8: 1 | D8: 0.4 | E8: 0.5 | F8: 1
A9: =Modules!A9 | B9: =Modules!B9 | C9: 1 | D9: 0.3 | E9: 1 | F9: 0
A10: =Modules!A10 | B10: =Modules!B10 | C10: 1 | D10: 0.3 | E10: 1 | F10: 0
A11: =Modules!A11 | B11: =Modules!B11 | C11: 1 | D11: 0.5 | E11: 0 | F11: 1
A12: =Modules!A12 | B12: =Modules!B12 | C12: 1 | D12: 0.6 | E12: 0.7 | F12: 0.5
A13: =Modules!A13 | B13: =Modules!B13 | C13: 0 | D13: 0 | E13: 0 | F13: 0
A14: =Modules!A14 | B14: =Modules!B14 | C14: 0 | D14: 0 | E14: 0 | F14: 0
A15: Note: P2 factors assume the same stack and MCU family as an ECU already delivered. P4 assumes the HSM and crypto stack are already integrated on the ECU. All factors are Claude's assumptions.
B17: Effort (hours)
B18: Core engineering hours (baseline, no AI) | C18: =SUMPRODUCT(Modules!$F$5:$F$14,C5:C14) | D18: =SUMPRODUCT(Modules!$F$5:$F$14,D5:D14) | E18: =SUMPRODUCT(Modules!$F$5:$F$14,E5:E14) | F18: =SUMPRODUCT(Modules!$F$5:$F$14,F5:F14)
B19: Evidence hours (ASPICE SWE.2-6 for the scope) | C19: =C18*Inputs!$B$8 | D19: =D18*Inputs!$B$8 | E19: =E18*Inputs!$B$8 | F19: =F18*Inputs!$B$8
B20: Customer-equivalent hours (what a team without AI needs) | C20: =C18+C19 | D20: =D18+D19 | E20: =E18+E19 | F20: =F18+F19
B21: PM, reviews and named sign-off hours | C21: =C20*Inputs!$B$9 | D21: =D20*Inputs!$B$9 | E21: =E20*Inputs!$B$9 | F21: =F20*Inputs!$B$9
B22: Our engineering hours after AI | C22: =C18*(1-Inputs!$B$10) | D22: =D18*(1-Inputs!$B$10) | E22: =E18*(1-Inputs!$B$10) | F22: =F18*(1-Inputs!$B$10)
B23: Our evidence hours after AI | C23: =C19*(1-Inputs!$B$11) | D23: =D19*(1-Inputs!$B$11) | E23: =E19*(1-Inputs!$B$11) | F23: =F19*(1-Inputs!$B$11)
B24: Contingency hours | C24: =(C21+C22+C23)*Inputs!$B$12 | D24: =(D21+D22+D23)*Inputs!$B$12 | E24: =(E21+E22+E23)*Inputs!$B$12 | F24: =(F21+F22+F23)*Inputs!$B$12
B25: Our total delivery hours | C25: =C21+C22+C23+C24 | D25: =D21+D22+D23+D24 | E25: =E21+E22+E23+E24 | F25: =F21+F22+F23+F24
B26: Our person-months | C26: =C25/Inputs!$B$6 | D26: =D25/Inputs!$B$6 | E26: =E25/Inputs!$B$6 | F26: =F25/Inputs!$B$6
B27: Calendar weeks with the delivery team | C27: =IF(Inputs!$B$18*Inputs!$B$19=0,0,C25/(Inputs!$B$18*Inputs!$B$19)) | D27: =IF(Inputs!$B$18*Inputs!$B$19=0,0,D25/(Inputs!$B$18*Inputs!$B$19)) | E27: =IF(Inputs!$B$18*Inputs!$B$19=0,0,E25/(Inputs!$B$18*Inputs!$B$19)) | F27: =IF(Inputs!$B$18*Inputs!$B$19=0,0,F25/(Inputs!$B$18*Inputs!$B$19))
B29: Price (EUR)
B30: Delivery cost | C30: =C25*Inputs!$B$7 | D30: =D25*Inputs!$B$7 | E30: =E25*Inputs!$B$7 | F30: =F25*Inputs!$B$7
B31: A) Cost-plus floor price (covers margin + guarantee reserve) | C31: =IF(1-Inputs!$B$14-Inputs!$B$13<=0,0,C30/(1-Inputs!$B$14-Inputs!$B$13)) | D31: =IF(1-Inputs!$B$14-Inputs!$B$13<=0,0,D30/(1-Inputs!$B$14-Inputs!$B$13)) | E31: =IF(1-Inputs!$B$14-Inputs!$B$13<=0,0,E30/(1-Inputs!$B$14-Inputs!$B$13)) | F31: =IF(1-Inputs!$B$14-Inputs!$B$13<=0,0,F30/(1-Inputs!$B$14-Inputs!$B$13))
B32: B) Value-based price (customer hours x reference rate, less AI pass-through) | C32: =C20*Inputs!$B$15*(1-Inputs!$B$16*Inputs!$B$10) | D32: =D20*Inputs!$B$15*(1-Inputs!$B$16*Inputs!$B$10) | E32: =E20*Inputs!$B$15*(1-Inputs!$B$16*Inputs!$B$10) | F32: =F20*Inputs!$B$15*(1-Inputs!$B$16*Inputs!$B$10)
B33: Recommended price = higher of A and B, rounded up | C33: =IF(Inputs!$B$17=0,MAX(C31,C32),ROUNDUP(MAX(C31,C32)/Inputs!$B$17,0)*Inputs!$B$17) | D33: =IF(Inputs!$B$17=0,MAX(D31,D32),ROUNDUP(MAX(D31,D32)/Inputs!$B$17,0)*Inputs!$B$17) | E33: =IF(Inputs!$B$17=0,MAX(E31,E32),ROUNDUP(MAX(E31,E32)/Inputs!$B$17,0)*Inputs!$B$17) | F33: =IF(Inputs!$B$17=0,MAX(F31,F32),ROUNDUP(MAX(F31,F32)/Inputs!$B$17,0)*Inputs!$B$17)
B34: Guarantee reserve | C34: =C33*Inputs!$B$13 | D34: =D33*Inputs!$B$13 | E34: =E33*Inputs!$B$13 | F34: =F33*Inputs!$B$13
B35: Gross profit | C35: =C33-C30-C34 | D35: =D33-D30-D34 | E35: =E33-E30-E34 | F35: =F33-F30-F34
B36: Gross margin | C36: =IF(C33=0,0,C35/C33) | D36: =IF(D33=0,0,D35/D33) | E36: =IF(E33=0,0,E35/E33) | F36: =IF(F33=0,0,F35/F33)
B37: Price per customer-equivalent hour (EUR/h) | C37: =IF(C20=0,0,C33/C20) | D37: =IF(D20=0,0,D33/D20) | E37: =IF(E20=0,0,E33/E20) | F37: =IF(F20=0,0,F33/F20)
B39: Customer's alternative cost for the same scope (EUR)
B40: German ESP / vendor (low) | C40: =C20*Inputs!$B$24 | D40: =D20*Inputs!$B$24 | E40: =E20*Inputs!$B$24 | F40: =F20*Inputs!$B$24
B41: German ESP / vendor (high) | C41: =C20*Inputs!$C$24 | D41: =D20*Inputs!$C$24 | E41: =E20*Inputs!$C$24 | F41: =F20*Inputs!$C$24
B42: DACH freelancer (low) | C42: =C20*Inputs!$B$25 | D42: =D20*Inputs!$B$25 | E42: =E20*Inputs!$B$25 | F42: =F20*Inputs!$B$25
B43: DACH freelancer (high) | C43: =C20*Inputs!$C$25 | D43: =D20*Inputs!$C$25 | E43: =E20*Inputs!$C$25 | F43: =F20*Inputs!$C$25
B44: Eastern Europe ESP (low) | C44: =C20*Inputs!$B$26 | D44: =D20*Inputs!$B$26 | E44: =E20*Inputs!$B$26 | F44: =F20*Inputs!$B$26
...

Sheet AI scenarios
A1: P1 Secure ECU Package: what AI leverage does to cost and margin
A2: Each row applies one AI saving to engineering and evidence hours. Column D keeps today's P1 price; columns E-F recalculate it.
A4: AI saving (eng. + evidence) | B4: Our total hours | C4: Delivery cost (EUR) | D4: Margin at current P1 price | E4: Recalculated price (EUR) | F4: Margin at recalculated price
A5: 0 | B5: =(Packages!$C$18*(1-A5)+Packages!$C$19*(1-A5)+Packages!$C$21)*(1+Inputs!$B$12) | C5: =B5*Inputs!$B$7 | D5: =IF(Packages!$C$33=0,0,(Packages!$C$33-C5-Packages!$C$33*Inputs!$B$13)/Packages!$C$33) | E5: =IF(Inputs!$B$17=0,0,ROUNDUP(MAX(IF(1-Inputs!$B$14-Inputs!$B$13<=0,0,C5/(1-Inputs!$B$14-Inputs!$B$13)),Packages!$C$20*Inputs!$B$15*(1-Inputs!$B$16*A5))/Inputs!$B$17,0)*Inputs!$B$17) | F5: =IF(E5=0,0,(E5-C5-E5*Inputs!$B$13)/E5)
A6: 0.15 | B6: =(Packages!$C$18*(1-A6)+Packages!$C$19*(1-A6)+Packages!$C$21)*(1+Inputs!$B$12) | C6: =B6*Inputs!$B$7 | D6: =IF(Packages!$C$33=0,0,(Packages!$C$33-C6-Packages!$C$33*Inputs!$B$13)/Packages!$C$33) | E6: =IF(Inputs!$B$17=0,0,ROUNDUP(MAX(IF(1-Inputs!$B$14-Inputs!$B$13<=0,0,C6/(1-Inputs!$B$14-Inputs!$B$13)),Packages!$C$20*Inputs!$B$15*(1-Inputs!$B$16*A6))/Inputs!$B$17,0)*Inputs!$B$17) | F6: =IF(E6=0,0,(E6-C6-E6*Inputs!$B$13)/E6)
A7: 0.3 | B7: =(Packages!$C$18*(1-A7)+Packages!$C$19*(1-A7)+Packages!$C$21)*(1+Inputs!$B$12) | C7: =B7*Inputs!$B$7 | D7: =IF(Packages!$C$33=0,0,(Packages!$C$33-C7-Packages!$C$33*Inputs!$B$13)/Packages!$C$33) | E7: =IF(Inputs!$B$17=0,0,ROUNDUP(MAX(IF(1-Inputs!$B$14-Inputs!$B$13<=0,0,C7/(1-Inputs!$B$14-Inputs!$B$13)),Packages!$C$20*Inputs!$B$15*(1-Inputs!$B$16*A7))/Inputs!$B$17,0)*Inputs!$B$17) | F7: =IF(E7=0,0,(E7-C7-E7*Inputs!$B$13)/E7)
A8: 0.45 | B8: =(Packages!$C$18*(1-A8)+Packages!$C$19*(1-A8)+Packages!$C$21)*(1+Inputs!$B$12) | C8: =B8*Inputs!$B$7 | D8: =IF(Packages!$C$33=0,0,(Packages!$C$33-C8-Packages!$C$33*Inputs!$B$13)/Packages!$C$33) | E8: =IF(Inputs!$B$17=0,0,ROUNDUP(MAX(IF(1-Inputs!$B$14-Inputs!$B$13<=0,0,C8/(1-Inputs!$B$14-Inputs!$B$13)),Packages!$C$20*Inputs!$B$15*(1-Inputs!$B$16*A8))/Inputs!$B$17,0)*Inputs!$B$17) | F8: =IF(E8=0,0,(E8-C8-E8*Inputs!$B$13)/E8)
A9: 0.6 | B9: =(Packages!$C$18*(1-A9)+Packages!$C$19*(1-A9)+Packages!$C$21)*(1+Inputs!$B$12) | C9: =B9*Inputs!$B$7 | D9: =IF(Packages!$C$33=0,0,(Packages!$C$33-C9-Packages!$C$33*Inputs!$B$13)/Packages!$C$33) | E9: =IF(Inputs!$B$17=0,0,ROUNDUP(MAX(IF(1-Inputs!$B$14-Inputs!$B$13<=0,0,C9/(1-Inputs!$B$14-Inputs!$B$13)),Packages!$C$20*Inputs!$B$15*(1-Inputs!$B$16*A9))/Inputs!$B$17,0)*Inputs!$B$17) | F9: =IF(E9=0,0,(E9-C9-E9*Inputs!$B$13)/E9)

Sheet Notes
A1: Secure ECU Package pricing model: notes
A2: Built 2026-10-25 for Phase 5 (sk-offer). Session: ai-automotive-sw.
A4: How the price is set
A5: 1. Module hours (Modules) x package factors (Packages) = core engineering hours for each package, without AI.
A6: 2. Evidence and PM/sign-off hours are added as percentages (Inputs).
A7: 3. Our delivery hours apply the AI saving and a contingency; cost = hours x internal cost per hour.
A8: 4. Price A (cost-plus floor) secures the target margin after the guarantee reserve.
A9: 5. Price B (value-based) prices the customer-equivalent hours at the market reference rate, minus the share of the AI saving passed through.
A10: 6. Recommended price = the higher of A and B, rounded up. Never quote hours or day rates to buyers; quote per package only.
A12: Data status
A13: Founder-supplied: total effort for a full security scope on one ECU = 3-6 person-months (480-960 h), without AI, from past programmes (memory, not timesheets).
A14: Claude's estimates: the split of that total across modules, all package factors, evidence %, PM %, contingency, AI saving, internal cost/h.
... A21: - Phase 7 (money model) will test these prices against buyer interviews (Phase 6).
